Workbook

Sheet SalesData
A1: OrderID | B1: OrderDate | C1: Product | D1: Region | E1: Channel | F1: CustomerSegment | G1: Salesperson | H1: Quantity | I1: UnitPrice | J1: Discount | K1: Revenue | L1: Cost | M1: Profit | N1: Month
A2: SO-00001 | B2: 45872 | C2: Headset | D2: East | E2: Retail Store | F2: Consumer | G2: Sara | H2: 4 | I2: 81.76 | J2: 0.05 | K2: 310.69 | L2: 199.89 | M2: 110.8 | N2: 2025-08
A3: SO-00002 | B3: 45849 | C3: RAM | D3: West | E3: Online | F3: Consumer | G3: Maryam | H3: 7 | I3: 76.85 | J3: 0.1 | K3: 484.15 | L3: 334.86 | M3: 149.29 | N3: 2025-07
A4: SO-00003 | B4: 45845 | C4: Laptop | D4: West | E4: Online | F4: Consumer | G4: Maryam | H4: 3 | I4: 859.38 | J4: 0.03 | K4: 2500.8 | L4: 1519.39 | M4: 981.41 | N4: 2025-07
A5: SO-00004 | B5: 45678 | C5: Keyboard | D5: North | E5: Online | F5: Enterprise | G5: Hassan | H5: 3 | I5: 55.16 | J5: 0 | K5: 165.47 | L5: 116.08 | M5: 49.39 | N5: 2025-01
A6: SO-00005 | B6: 45921 | C6: Docking Station | D6: East | E6: Online | F6: Consumer | G6: Bilal | H6: 1 | I6: 141.68 | J6: 0 | K6: 141.68 | L6: 89 | M6: 52.68 | N6: 2025-09
A7: SO-00006 | B7: 45848 | C7: SSD | D7: South | E7: Retail Store | F7: Enterprise | G7: Maryam | H7: 3 | I7: 105.86 | J7: 0.05 | K7: 301.69 | L7: 195.93 | M7: 105.76 | N7: 2025-07
A8: SO-00007 | B8: 45847 | C8: Smartphone | D8: West | E8: Corporate | F8: Small Business | G8: Omid | H8: 2 | I8: 648.18 | J8: 0.05 | K8: 1231.55 | L8: 886.93 | M8: 344.62 | N8: 2025-07
A9: SO-00008 | B9: 45672 | C9: Tablet | D9: North | E9: Online | F9: Enterprise | G9: Sara | H9: 2 | I9: 330.26 | J9: 0.05 | K9: 627.49 | L9: 401.72 | M9: 225.77 | N9: 2025-01
A10: SO-00009 | B10: 45946 | C10: Headset | D10: East | E10: Online | F10: Consumer | G10: Aisha | H10: 1 | I10: 71.9 | J10: 0 | K10: 71.9 | L10: 51.93 | M10: 19.97 | N10: 2025-10
A11: SO-00010 | B11: 45719 | C11: Smartphone | D11: West | E11: Retail Store | F11: Small Business | G11: Maryam | H11: 2 | I11: 663.4 | J11: 0 | K11: 1326.81 | L11: 867.95 | M11: 458.86 | N11: 2025-03
A12: SO-00011 | B12: 45875 | C12: Tablet | D12: East | E12: Retail Store | F12: Consumer | G12: Aisha | H12: 1 | I12: 338.11 | J12: 0.05 | K12: 321.21 | L12: 247.55 | M12: 73.66 | N12: 2025-08
A13: SO-00012 | B13: 45898 | C13: RAM | D13: West | E13: Retail Store | F13: Small Business | G13: Lina | H13: 2 | I13: 78.39 | J13: 0 | K13: 156.77 | L13: 119.01 | M13: 37.76 | N13: 2025-08
... A1201: SO-01200 | B1201: 45990 | C1201: SSD | D1201: South | E1201: Online | F1201: Consumer | G1201: Aisha | H1201: 6 | I1201: 105.25 | J1201: 0.03 | K1201: 612.55 | L1201: 402.86 | M1201: 209.69 | N1201: 2025-11

Sheet Product Analysis
B1: Total Revenue | C1: Total Profit | D1: Total Units Sold | E1: AOV | F1: Profit Margin | G1: Top Selling Product | H1: Top Performing Region | I1: Top Performing SP
B2: =SUM(Table4[Revenue]) -> 870310.37 | C2: =SUM(Table4[Profit]) -> 244411.19 | D2: =SUM(Table4[Quantity]) -> 3525 | E2: =B2/D2 -> 246.89656 | F2: =C2/B2 -> 0.28083222 | G2: =INDEX('Product Analysis'!G6:G17, MATCH(MAX('Product Analysis'!H6:H17),'Product Analysis'!H6:H17,0)) -> Laptop | H2: =INDEX(_xlfn.ANCHORARRAY('Product Analysis'!M49),MATCH(MAX(_xlfn.ANCHORARRAY('Product Analysis'!N49)),_xlfn.ANCHORARRAY('Product Analysis'!N49),0)) -> North | I2: =INDEX(Table4[Salesperson],MATCH(MAX(_xlfn.ANCHORARRAY(K49)),_xlfn.ANCHORARRAY(K49),0)) -> Omid
B5: Product | C5: Revenue | D5: Profit | E5: Units Sold | G5: Product | H5: Revenue | I5: Profit
B6: {=_xlfn.UNIQUE(SalesData!C2:C1201)} -> Headset | C6: {=SUMIFS(Table4[Revenue],Table4[Product],_xlfn.ANCHORARRAY('Product Analysis'!B6))} -> 18987.39 | D6: {=SUMIFS(Table4[Profit],Table4[Product],_xlfn.ANCHORARRAY('Product Analysis'!B6))} -> 5574.23 | E6: {=SUMIFS(Table4[Quantity],Table4[Product],_xlfn.ANCHORARRAY('Product Analysis'!B6))} -> 265 | G6: {=_xlfn.SORTBY(B6:D17,_xlfn.ANCHORARRAY(C6),-1)} -> Laptop | H6: 315460.52 | I6: 88361.63
B7: RAM | C7: 21457.36 | D7: 5853.88 | E7: 265 | G7: Smartphone | H7: 182656.38 | I7: 50552.9
B8: Laptop | C8: 315460.52 | D8: 88361.63 | E8: 352 | G8: Tablet | H8: 89667.17 | I8: 26344.82
B9: Keyboard | C9: 17215.1 | D9: 5005.37 | E9: 329 | G9: Monitor | H9: 73751.1 | I9: 20441.88
B10: Docking Station | C10: 39373.31 | D10: 11353.37 | E10: 283 | G10: Printer | H10: 44824.93 | I10: 12034.92
B11: SSD | C11: 31037.72 | D11: 8588.79 | E11: 294 | G11: Docking Station | H11: 39373.31 | I11: 11353.37
B12: Smartphone | C12: 182656.38 | D12: 50552.9 | E12: 311 | G12: SSD | H12: 31037.72 | I12: 8588.79
B13: Tablet | C13: 89667.17 | D13: 26344.82 | E13: 272 | G13: Webcam | H13: 24949.81 | I13: 7286.58
B14: Mouse | C14: 10929.58 | D14: 3012.82 | E14: 358 | G14: RAM | H14: 21457.36 | I14: 5853.88
B15: Printer | C15: 44824.93 | D15: 12034.92 | E15: 251 | G15: Headset | H15: 18987.39 | I15: 5574.23
B16: Monitor | C16: 73751.1 | D16: 20441.88 | E16: 272 | G16: Keyboard | H16: 17215.1 | I16: 5005.37
B17: Webcam | C17: 24949.81 | D17: 7286.58 | E17: 273 | G17: Mouse | H17: 10929.58 | I17: 3012.82
B19: Region | C19: East
B20: Channel | C20: Retail Store
B21: Customer Segment | C21: Small Business
B22: Max Revenue | C22: 7785.96
B23: Min Revenue | C23: 25.87 | H23: Data Quality Monitor
B24: OrderID | C24: Product | D24: Region | E24: Channel | F24: Revenue | H24: Zero Quantity Orders
B25: {=_xlfn.CHOOSECOLS(_xlfn._xlws.SORT(_xlfn._xlws.FILTER(Table4[],(Table4[Region]=C19)*(Table4[Channel]=C20)*(Table4[CustomerSegment]=C21)*(Table4[Revenue]>=C23)*(Table4[Revenue]<=C22)),11,-1),1,3,4,5,11)} -> SO-00290 | C25: Laptop | D25: East | E25: Retail Store | F25: 3760.51 | H25: OrderID | I25: OrderDate | J25: Product | K25: Region | L25: Channel | M25: CustomerSegment | N25: Salesperson | O25: Quantity | P25: UnitPrice | Q25: Discount | R25: Revenue | S25: Cost | T25: Profit | U25: Month
B26: SO-00929 | C26: Smartphone | D26: East | E26: Retail Store | F26: 3744.03 | H26: {=_xlfn._xlws.FILTER(Table4[],Table4[Quantity] = 0,"No issues found")} -> SO-00094 | I26: 45806 | J26: Monitor | K26: East | L26: Online | M26: Consumer | N26: Hassan | O26: 0 | P26: 303.57 | Q26: 0.05 | R26: 1441.94 | S26: 1059.84 | T26: 382.1 | U26: 2025-05
B27: SO-00805 | C27: Laptop | D27: East | E27: Retail Store | F27: 3506.32 | H27: SO-00292 | I27: 46012 | J27: Webcam | K27: West | L27: Online | M27: Small Business | N27: Lina | O27: 0 | P27: 86.98 | Q27: 0.03 | R27: 168.73 | S27: 103.19 | T27: 65.54 | U27: 2025-12
B28: SO-00254 | C28: Smartphone | D28: East | E28: Retail Store | F28: 2377.54 | H28: SO-00397 | I28: 45769 | J28: Keyboard | K28: North | L28: Retail Store | M28: Small Business | N28: Hassan | O28: 0 | P28: 49.97 | Q28: 0.05 | R28: 142.4 | S28: 115.38 | T28: 27.02 | U28: 2025-04
B29: SO-00936 | C29: Tablet | D29: East | E29: Retail Store | F29: 1190.09 | H29: SO-00418 | I29: 45926 | J29: SSD | K29: East | L29: Online | M29: Consumer | N29: Omid | O29: 0 | P29: 120.99 | Q29: 0.03 | R29: 469.44 | S29: 360.8 | T29: 108.64 | U29: 2025-09
B30: SO-00935 | C30: Smartphone | D30: East | E30: Retail Store | F30: 1009.36 | H30: High Discount Orders
B31: SO-00923 | C31: Smartphone | D31: East | E31: Retail Store | F31: 634.69 | H31: OrderID | I31: OrderDate | J31: Product | K31: Region | L31: Channel | M31: CustomerSegment | N31: Salesperson | O31: Quantity | P31: UnitPrice | Q31: Discount | R31: Revenue | S31: Cost | T31: Profit | U31: Month
B32: SO-00741 | C32: Printer | D32: East | E32: Retail Store | F32: 519.31 | H32: {=_xlfn._xlws.FILTER(Table4[],Table4[Discount]>20%,"No issues fount")} -> SO-00205 | I32: 46000 | J32: Printer | K32: West | L32: Corporate | M32: Consumer | N32: Hassan | O32: 2 | P32: 189.83 | Q32: 0.3 | R32: 360.67 | S32: 237.43 | T32: 123.24 | U32: 2025-12
B33: SO-00314 | C33: Docking Station | D33: East | E33: Retail Store | F33: 425.73 | H33: SO-00209 | I33: 45762 | J33: Smartphone | K33: North | L33: Corporate | M33: Consumer | N33: Omid | O33: 1 | P33: 640.75 | Q33: 0.3 | R33: 621.53 | S33: 405.05 | T33: 216.48 | U33: 2025-04
B34: SO-01024 | C34: RAM | D34: East | E34: Retail Store | F34: 352.7 | H34: SO-00363 | I34: 45778 | J34: Laptop | K34: North | L34: Corporate | M34: Consumer | N34: Lina | O34: 2 | P34: 894.91 | Q34: 0.3 | R34: 1700.32 | S34: 1042.2 | T34: 658.12 | U34: 2025-05
B35: SO-00109 | C35: Tablet | D35: East | E35: Retail Store | F35: 320.04 | H35: SO-00955 | I35: 45937 | J35: Mouse | K35: West | L35: Retail Store | M35: Small Business | N35: Lina | O35: 4 | P35: 34.35 | Q35: 0.3 | R35: 123.65 | S35: 93.29 | T35: 30.36 | U35: 2025-10
B36: SO-00908 | C36: RAM | D36: East | E36: Retail Store | F36: 318.62 | H36: Suspicious Transactions
B37: SO-00347 | C37: Headset | D37: East | E37: Retail Store | F37: 312.48 | H37: OrderID | I37: OrderDate | J37: Product | K37: Region | L37: Channel | M37: CustomerSegment | N37: Salesperson | O37: Quantity | P37: UnitPrice | Q37: Discount | R37: Revenue | S37: Cost | T37: Profit | U37: Month
B38: SO-00504 | C38: Monitor | D38: East | E38: Retail Store | F38: 246.15 | H38: {=_xlfn.SORTBY(_xlfn._xlws.FILTER(Table4[],(Table4[Quantity]=0)+(Table4[Discount]>20%)),_xlfn._xlws.FILTER(Table4[Revenue], (Table4[Quantity]=0)+(Table4[Discount]>20%)), -1)} -> SO-00363 | I38: 45778 | J38: Laptop | K38: North | L38: Corporate | M38: Consumer | N38: Lina | O38: 2 | P38: 894.91 | Q38: 0.3 | R38: 1700.32 | S38: 1042.2 | T38: 658.12 | U38: 2025-05
B39: SO-00381 | C39: Headset | D39: East | E39: Retail Store | F39: 220.35 | H39: SO-00094 | I39: 45806 | J39: Monitor | K39: East | L39: Online | M39: Consumer | N39: Hassan | O39: 0 | P39: 303.57 | Q39: 0.05 | R39: 1441.94 | S39: 1059.84 | T39: 382.1 | U39: 2025-05
B40: SO-00891 | C40: SSD | D40: East | E40: Retail Store | F40: 218.72 | H40: SO-00209 | I40: 45762 | J40: Smartphone | K40: North | L40: Corporate | M40: Consumer | N40: Omid | O40: 1 | P40: 640.75 | Q40: 0.3 | R40: 621.53 | S40: 405.05 | T40: 216.48 | U40: 2025-04
B41: SO-01066 | C41: SSD | D41: East | E41: Retail Store | F41: 213.57 | H41: SO-00418 | I41: 45926 | J41: SSD | K41: East | L41: Online | M41: Consumer | N41: Omid | O41: 0 | P41: 120.99 | Q41: 0.03 | R41: 469.44 | S41: 360.8 | T41: 108.64 | U41: 2025-09
B42: SO-01156 | C42: Printer | D42: East | E42: Retail Store | F42: 208.63 | H42: SO-00205 | I42: 46000 | J42: Printer | K42: West | L42: Corporate | M42: Consumer | N42: Hassan | O42: 2 | P42: 189.83 | Q42: 0.3 | R42: 360.67 | S42: 237.43 | T42: 123.24 | U42: 2025-12
B43: SO-01110 | C43: Webcam | D43: East | E43: Retail Store | F43: 197.53 | H43: SO-00292 | I43: 46012 | J43: Webcam | K43: West | L43: Online | M43: Small Business | N43: Lina | O43: 0 | P43: 86.98 | Q43: 0.03 | R43: 168.73 | S43: 103.19 | T43: 65.54 | U43: 2025-12
...
